INFO:     Will watch for changes in these directories: ['/home/a/by/ui/backend']
INFO:     Uvicorn running on http://0.0.0.0:8000 (Press CTRL+C to quit)
INFO:     Started reloader process [1628097] using WatchFiles
Process SpawnProcess-1:
Traceback (most recent call last):
  File "/usr/lib/python3.12/multiprocessing/process.py", line 314, in _bootstrap
    self.run()
  File "/usr/lib/python3.12/multiprocessing/process.py", line 108, in run
    self._target(*self._args, **self._kwargs)
  File "/home/a/.local/lib/python3.12/site-packages/uvicorn/_subprocess.py", line 76, in subprocess_started
    target(sockets=sockets)
  File "/home/a/.local/lib/python3.12/site-packages/uvicorn/server.py", line 61, in run
    return asyncio.run(self.serve(sockets=sockets))
           ^^^^^^^^^^^^^^^^^^^^^^^^^^^^^^^^^^^^^^^^
  File "/usr/lib/python3.12/asyncio/runners.py", line 194, in run
    return runner.run(main)
           ^^^^^^^^^^^^^^^^
  File "/usr/lib/python3.12/asyncio/runners.py", line 118, in run
    return self._loop.run_until_complete(task)
           ^^^^^^^^^^^^^^^^^^^^^^^^^^^^^^^^^^^
  File "uvloop/loop.pyx", line 1518, in uvloop.loop.Loop.run_until_complete
  File "/home/a/.local/lib/python3.12/site-packages/uvicorn/server.py", line 68, in serve
    config.load()
  File "/home/a/.local/lib/python3.12/site-packages/uvicorn/config.py", line 467, in load
    self.loaded_app = import_from_string(self.app)
                      ^^^^^^^^^^^^^^^^^^^^^^^^^^^^
  File "/home/a/.local/lib/python3.12/site-packages/uvicorn/importer.py", line 21, in import_from_string
    module = importlib.import_module(module_str)
             ^^^^^^^^^^^^^^^^^^^^^^^^^^^^^^^^^^^
  File "/usr/lib/python3.12/importlib/__init__.py", line 90, in import_module
    return _bootstrap._gcd_import(name[level:], package, level)
           ^^^^^^^^^^^^^^^^^^^^^^^^^^^^^^^^^^^^^^^^^^^^^^^^^^^^
  File "<frozen importlib._bootstrap>", line 1387, in _gcd_import
  File "<frozen importlib._bootstrap>", line 1360, in _find_and_load
  File "<frozen importlib._bootstrap>", line 1331, in _find_and_load_unlocked
  File "<frozen importlib._bootstrap>", line 935, in _load_unlocked
  File "<frozen importlib._bootstrap_external>", line 995, in exec_module
  File "<frozen importlib._bootstrap>", line 488, in _call_with_frames_removed
  File "/home/a/by/ui/backend/app/main.py", line 3, in <module>
    from app.api.v1.router import api_router
  File "/home/a/by/ui/backend/app/api/v1/router.py", line 2, in <module>
    from app.api.v1 import (
  File "/home/a/by/ui/backend/app/api/v1/auth.py", line 7, in <module>
    from app.core.config import settings
  File "/home/a/by/ui/backend/app/core/config.py", line 38, in <module>
    settings = Settings()
               ^^^^^^^^^^
  File "/home/a/.local/lib/python3.12/site-packages/pydantic_settings/main.py", line 188, in __init__
    super().__init__(
  File "/home/a/.local/lib/python3.12/site-packages/pydantic/main.py", line 253, in __init__
    validated_self = self.__pydantic_validator__.validate_python(data, self_instance=self)
                     ^^^^^^^^^^^^^^^^^^^^^^^^^^^^^^^^^^^^^^^^^^^^^^^^^^^^^^^^^^^^^^^^^^^^^
pydantic_core._pydantic_core.ValidationError: 3 validation errors for Settings
DATABASE_URL
  Extra inputs are not permitted [type=extra_forbidden, input_value='sqlite:///./hsystem.db', input_type=str]
    For further information visit https://errors.pydantic.dev/2.11/v/extra_forbidden
DEBUG
  Extra inputs are not permitted [type=extra_forbidden, input_value='true', input_type=str]
    For further information visit https://errors.pydantic.dev/2.11/v/extra_forbidden
LOG_LEVEL
  Extra inputs are not permitted [type=extra_forbidden, input_value='INFO', input_type=str]
    For further information visit https://errors.pydantic.dev/2.11/v/extra_forbidden
